QStandardPaths: XDG_RUNTIME_DIR not set, defaulting to '/tmp/runtime-root'
libEGL warning: DRI2: failed to authenticate
Exception ignored in thread started by: <function updataWeather at 0x678c9bf8>
Traceback (most recent call last):
  File "/mirror/pycharm_project_365/UI.py", line 68, in updataWeather
    mainw.ui.label_weather.setText(wea.displayToUi('深圳'))
  File "/mirror/pycharm_project_365/clsWeather.py", line 22, in displayToUi
    self.get(i)
  File "/mirror/pycharm_project_365/clsWeather.py", line 12, in get
    data = requests.get(url).json()
  File "/usr/lib/python3/dist-packages/requests/api.py", line 76, in get
    return request('get', url, params=params, **kwargs)
  File "/usr/lib/python3/dist-packages/requests/api.py", line 61, in request
    return session.request(method=method, url=url, **kwargs)
  File "/usr/lib/python3/dist-packages/requests/sessions.py", line 542, in request
    resp = self.send(prep, **send_kwargs)
  File "/usr/lib/python3/dist-packages/requests/sessions.py", line 655, in send
    r = adapter.send(request, **kwargs)
  File "/usr/lib/python3/dist-packages/requests/adapters.py", line 516, in send
    raise ConnectionError(e, request=request)
requests.exceptions.ConnectionError: HTTPConnectionPool(host='wthrcdn.etouch.cn', port=80): Max retries exceeded with url: /weather_mini?city=%E6%B7%B1%E5%9C%B3 (Caused by NewConnectionError('<urllib3.connection.HTTPConnection object at 0x678d5cd0>: Failed to establish a new connection: [Errno -3] 域名解析暂时失败'))
Exception ignored in thread started by: <function update at 0x678c9220>
Traceback (most recent call last):
  File "/mirror/pycharm_project_365/UI.py", line 50, in update
    Text = GetHitokoto.get()
  File "/mirror/pycharm_project_365/GetHitokoto.py", line 10, in get
    __return = requests.get(__url, headers=__headers)
  File "/usr/lib/python3/dist-packages/requests/api.py", line 76, in get
    return request('get', url, params=params, **kwargs)
  File "/usr/lib/python3/dist-packages/requests/api.py", line 61, in request
    return session.request(method=method, url=url, **kwargs)
  File "/usr/lib/python3/dist-packages/requests/sessions.py", line 542, in request
    resp = self.send(prep, **send_kwargs)
  File "/usr/lib/python3/dist-packages/requests/sessions.py", line 655, in send
    r = adapter.send(request, **kwargs)
  File "/usr/lib/python3/dist-packages/requests/adapters.py", line 516, in send
    raise ConnectionError(e, request=request)
requests.exceptions.ConnectionError: HTTPSConnectionPool(host='v2.jinrishici.com', port=443): Max retries exceeded with url: /sentence (Caused by NewConnectionError('<urllib3.connection.HTTPSConnection object at 0x678d5148>: Failed to establish a new connection: [Errno -3] 域名解析暂时失败'))
271
<html><head/><body><p><span style=" font-size:26pt; font-weight:600; color:#ffffff;">待办：</span></p><p><span style=" font-size:16pt; color:#ffffff;">1.拿大奖</span></p></body></html>
1
1
1
-1
